<?xml version="1.0" encoding="UTF-8"?>
<testng-results skipped="0" failed="2" ignored="0" total="7" passed="5">
  <reporter-output>
  </reporter-output>
  <suite name="Suite" duration-ms="300" started-at="2022-02-22T10:06:30Z" finished-at="2022-02-22T10:06:30Z">
    <groups>
    </groups>
    <test name="Test" duration-ms="300" started-at="2022-02-22T10:06:30Z" finished-at="2022-02-22T10:06:30Z">
      <class name="com.jbk.Dashboard">
        <test-method status="PASS" signature="dash1()[pri:0, instance:com.jbk.Dashboard@5ad851c9]" name="dash1" duration-ms="14" started-at="2022-02-22T10:06:30Z" finished-at="2022-02-22T10:06:30Z">
          <reporter-output>
          </reporter-output>
        </test-method> <!-- dash1 -->
        <test-method status="PASS" signature="dash2()[pri:0, instance:com.jbk.Dashboard@5ad851c9]" name="dash2" duration-ms="2" started-at="2022-02-22T10:06:30Z" finished-at="2022-02-22T10:06:30Z">
          <reporter-output>
          </reporter-output>
        </test-method> <!-- dash2 -->
        <test-method status="FAIL" signature="dash3()[pri:0, instance:com.jbk.Dashboard@5ad851c9]" name="dash3" duration-ms="6" started-at="2022-02-22T10:06:30Z" finished-at="2022-02-22T10:06:30Z">
          <exception class="java.lang.AssertionError">
            <message>
              <![CDATA[expected [1] but found [2]]]>
            </message>
            <full-stacktrace>
              <![CDATA[java.lang.AssertionError: expected [1] but found [2]
at org.testng.Assert.fail(Assert.java:96)
at org.testng.Assert.failNotEquals(Assert.java:776)
at org.testng.Assert.assertEqualsImpl(Assert.java:137)
at org.testng.Assert.assertEquals(Assert.java:118)
at org.testng.Assert.assertEquals(Assert.java:652)
at org.testng.Assert.assertEquals(Assert.java:662)
at com.jbk.Dashboard.dash3(Dashboard.java:19)
at sun.reflect.NativeMethodAccessorImpl.invoke0(Native Method)
at sun.reflect.NativeMethodAccessorImpl.invoke(NativeMethodAccessorImpl.java:62)
at sun.reflect.DelegatingMethodAccessorImpl.invoke(DelegatingMethodAccessorImpl.java:43)
at java.lang.reflect.Method.invoke(Method.java:498)
at org.testng.internal.MethodInvocationHelper.invokeMethod(MethodInvocationHelper.java:124)
at org.testng.internal.Invoker.invokeMethod(Invoker.java:583)
at org.testng.internal.Invoker.invokeTestMethod(Invoker.java:719)
at org.testng.internal.Invoker.invokeTestMethods(Invoker.java:989)
at org.testng.internal.TestMethodWorker.invokeTestMethods(TestMethodWorker.java:125)
at org.testng.internal.TestMethodWorker.run(TestMethodWorker.java:109)
at org.testng.TestRunner.privateRun(TestRunner.java:648)
at org.testng.TestRunner.run(TestRunner.java:505)
at org.testng.SuiteRunner.runTest(SuiteRunner.java:455)
at org.testng.SuiteRunner.runSequentially(SuiteRunner.java:450)
at org.testng.SuiteRunner.privateRun(SuiteRunner.java:415)
at org.testng.SuiteRunner.run(SuiteRunner.java:364)
at org.testng.SuiteRunnerWorker.runSuite(SuiteRunnerWorker.java:52)
at org.testng.SuiteRunnerWorker.run(SuiteRunnerWorker.java:84)
at org.testng.TestNG.runSuitesSequentially(TestNG.java:1208)
at org.testng.TestNG.runSuitesLocally(TestNG.java:1137)
at org.testng.TestNG.runSuites(TestNG.java:1049)
at org.testng.TestNG.run(TestNG.java:1017)
at org.testng.remote.AbstractRemoteTestNG.run(AbstractRemoteTestNG.java:115)
at org.testng.remote.RemoteTestNG.initAndRun(RemoteTestNG.java:251)
at org.testng.remote.RemoteTestNG.main(RemoteTestNG.java:77)
]]>
            </full-stacktrace>
          </exception> <!-- java.lang.AssertionError -->
          <reporter-output>
          </reporter-output>
        </test-method> <!-- dash3 -->
      </class> <!-- com.jbk.Dashboard -->
      <class name="com.jbk.Demo">
        <test-method status="PASS" signature="test01()[pri:0, instance:com.jbk.Demo@6156496]" name="test01" duration-ms="5" started-at="2022-02-22T10:06:30Z" finished-at="2022-02-22T10:06:30Z">
          <reporter-output>
          </reporter-output>
        </test-method> <!-- test01 -->
        <test-method status="PASS" signature="test02()[pri:0, instance:com.jbk.Demo@6156496]" name="test02" duration-ms="3" started-at="2022-02-22T10:06:30Z" finished-at="2022-02-22T10:06:30Z">
          <reporter-output>
          </reporter-output>
        </test-method> <!-- test02 -->
      </class> <!-- com.jbk.Demo -->
      <class name="com.jbk.LoginTest">
        <test-method status="FAIL" signature="login01()[pri:0, instance:com.jbk.LoginTest@5c1a8622]" name="login01" duration-ms="41" started-at="2022-02-22T10:06:30Z" finished-at="2022-02-22T10:06:30Z">
          <exception class="java.lang.AssertionError">
            <message>
              <![CDATA[expected [true] but found [false]]]>
            </message>
            <full-stacktrace>
              <![CDATA[java.lang.AssertionError: expected [true] but found [false]
at org.testng.Assert.fail(Assert.java:96)
at org.testng.Assert.failNotEquals(Assert.java:776)
at org.testng.Assert.assertTrue(Assert.java:44)
at org.testng.Assert.assertTrue(Assert.java:54)
at com.jbk.LoginTest.login01(LoginTest.java:9)
at sun.reflect.NativeMethodAccessorImpl.invoke0(Native Method)
at sun.reflect.NativeMethodAccessorImpl.invoke(NativeMethodAccessorImpl.java:62)
at sun.reflect.DelegatingMethodAccessorImpl.invoke(DelegatingMethodAccessorImpl.java:43)
at java.lang.reflect.Method.invoke(Method.java:498)
at org.testng.internal.MethodInvocationHelper.invokeMethod(MethodInvocationHelper.java:124)
at org.testng.internal.Invoker.invokeMethod(Invoker.java:583)
at org.testng.internal.Invoker.invokeTestMethod(Invoker.java:719)
at org.testng.internal.Invoker.invokeTestMethods(Invoker.java:989)
at org.testng.internal.TestMethodWorker.invokeTestMethods(TestMethodWorker.java:125)
at org.testng.internal.TestMethodWorker.run(TestMethodWorker.java:109)
at org.testng.TestRunner.privateRun(TestRunner.java:648)
at org.testng.TestRunner.run(TestRunner.java:505)
at org.testng.SuiteRunner.runTest(SuiteRunner.java:455)
at org.testng.SuiteRunner.runSequentially(SuiteRunner.java:450)
at org.testng.SuiteRunner.privateRun(SuiteRunner.java:415)
at org.testng.SuiteRunner.run(SuiteRunner.java:364)
at org.testng.SuiteRunnerWorker.runSuite(SuiteRunnerWorker.java:52)
at org.testng.SuiteRunnerWorker.run(SuiteRunnerWorker.java:84)
at org.testng.TestNG.runSuitesSequentially(TestNG.java:1208)
at org.testng.TestNG.runSuitesLocally(TestNG.java:1137)
at org.testng.TestNG.runSuites(TestNG.java:1049)
at org.testng.TestNG.run(TestNG.java:1017)
at org.testng.remote.AbstractRemoteTestNG.run(AbstractRemoteTestNG.java:115)
at org.testng.remote.RemoteTestNG.initAndRun(RemoteTestNG.java:251)
at org.testng.remote.RemoteTestNG.main(RemoteTestNG.java:77)
]]>
            </full-stacktrace>
          </exception> <!-- java.lang.AssertionError -->
          <reporter-output>
          </reporter-output>
        </test-method> <!-- login01 -->
        <test-method status="PASS" signature="login02()[pri:0, instance:com.jbk.LoginTest@5c1a8622]" name="login02" duration-ms="4" started-at="2022-02-22T10:06:30Z" finished-at="2022-02-22T10:06:30Z">
          <reporter-output>
          </reporter-output>
        </test-method> <!-- login02 -->
      </class> <!-- com.jbk.LoginTest -->
    </test> <!-- Test -->
  </suite> <!-- Suite -->
</testng-results>
